[2024-10-21T03:10:45.599+0000] {local_task_job_runner.py:123} INFO - ::group::Pre task execution logs
[2024-10-21T03:10:45.697+0000] {taskinstance.py:2612} INFO - Dependencies all met for dep_context=non-requeueable deps ti=<TaskInstance: elt.transform_data.run_dim_item manual__2024-10-21T03:09:40.637302+00:00 [queued]>
[2024-10-21T03:10:45.715+0000] {taskinstance.py:2612} INFO - Dependencies all met for dep_context=requeueable deps ti=<TaskInstance: elt.transform_data.run_dim_item manual__2024-10-21T03:09:40.637302+00:00 [queued]>
[2024-10-21T03:10:45.716+0000] {taskinstance.py:2865} INFO - Starting attempt 1 of 2
[2024-10-21T03:10:45.786+0000] {taskinstance.py:2888} INFO - Executing <Task(PostgresOperator): transform_data.run_dim_item> on 2024-10-21 03:09:40.637302+00:00
[2024-10-21T03:10:45.899+0000] {standard_task_runner.py:104} INFO - Running: ['***', 'tasks', 'run', 'elt', 'transform_data.run_dim_item', 'manual__2024-10-21T03:09:40.637302+00:00', '--job-id', '121', '--raw', '--subdir', 'DAGS_FOLDER/elt.py', '--cfg-path', '/tmp/tmp0zwqc_fz']
[2024-10-21T03:10:45.893+0000] {warnings.py:112} WARNING - /home/***/.local/lib/python3.12/site-packages/***/task/task_runner/standard_task_runner.py:70: DeprecationWarning: This process (pid=305) is multi-threaded, use of fork() may lead to deadlocks in the child.
  pid = os.fork()

[2024-10-21T03:10:45.945+0000] {standard_task_runner.py:105} INFO - Job 121: Subtask transform_data.run_dim_item
[2024-10-21T03:10:45.946+0000] {standard_task_runner.py:72} INFO - Started process 310 to run task
[2024-10-21T03:10:53.651+0000] {task_command.py:467} INFO - Running <TaskInstance: elt.transform_data.run_dim_item manual__2024-10-21T03:09:40.637302+00:00 [running]> on host 6c3793bbe9c9
[2024-10-21T03:10:54.388+0000] {taskinstance.py:3131} INFO - Exporting env vars: AIRFLOW_CTX_DAG_OWNER='mherszage' AIRFLOW_CTX_DAG_ID='elt' AIRFLOW_CTX_TASK_ID='transform_data.run_dim_item' AIRFLOW_CTX_EXECUTION_DATE='2024-10-21T03:09:40.637302+00:00' AIRFLOW_CTX_TRY_NUMBER='1' AIRFLOW_CTX_DAG_RUN_ID='manual__2024-10-21T03:09:40.637302+00:00'
[2024-10-21T03:10:54.431+0000] {taskinstance.py:731} INFO - ::endgroup::
[2024-10-21T03:10:54.561+0000] {sql.py:266} INFO - Executing: BEGIN TRANSACTION
;

CREATE TEMPORARY TABLE staging_dim_item AS
(
WITH filter_variables AS
(SELECT COALESCE(MAX(_dim_item_audit_time), '2024-10-16'::timestamp) AS last_updated FROM "2024_melissa_herszage_schema".l2_dim_item)

    SELECT id as item_id,
        title,
        created_at as _l1_audit_time,
        current_timestamp as _dim_item_audit_time
    FROM "2024_melissa_herszage_schema".l1_items as i
    CROSS JOIN filter_variables fv
    WHERE i.created_at > last_updated
    )
;

DELETE FROM "2024_melissa_herszage_schema".l2_dim_item
WHERE item_id IN (SELECT item_id FROM staging_dim_item)
;

INSERT INTO "2024_melissa_herszage_schema".l2_dim_item
(SELECT * FROM staging_dim_item)
;

END TRANSACTION
;
[2024-10-21T03:10:54.965+0000] {base.py:84} INFO - Retrieving connection 'redshift_default'
[2024-10-21T03:10:56.391+0000] {base.py:84} INFO - Retrieving connection 'redshift_default'
[2024-10-21T03:10:56.597+0000] {job.py:229} INFO - Heartbeat recovered after 11.56 seconds
[2024-10-21T03:11:04.177+0000] {sql.py:509} INFO - Running statement: BEGIN TRANSACTION
;

CREATE TEMPORARY TABLE staging_dim_item AS
(
WITH filter_variables AS
(SELECT COALESCE(MAX(_dim_item_audit_time), '2024-10-16'::timestamp) AS last_updated FROM "2024_melissa_herszage_schema".l2_dim_item)

    SELECT id as item_id,
        title,
        created_at as _l1_audit_time,
        current_timestamp as _dim_item_audit_time
    FROM "2024_melissa_herszage_schema".l1_items as i
    CROSS JOIN filter_variables fv
    WHERE i.created_at > last_updated
    )
;

DELETE FROM "2024_melissa_herszage_schema".l2_dim_item
WHERE item_id IN (SELECT item_id FROM staging_dim_item)
;

INSERT INTO "2024_melissa_herszage_schema".l2_dim_item
(SELECT * FROM staging_dim_item)
;

END TRANSACTION
;, parameters: None
[2024-10-21T03:11:04.883+0000] {taskinstance.py:3310} ERROR - Task failed with exception
Traceback (most recent call last):
  File "/home/airflow/.local/lib/python3.12/site-packages/redshift_connector/core.py", line 1830, in execute
    ps = cache["ps"][key]
         ~~~~~~~~~~~^^^^^
KeyError: ('BEGIN TRANSACTION\n;\n\nCREATE TEMPORARY TABLE staging_dim_item AS\n(\nWITH filter_variables AS\n(SELECT COALESCE(MAX(_dim_item_audit_time), \'2024-10-16\'::timestamp) AS last_updated FROM "2024_melissa_herszage_schema".l2_dim_item)\n\n    SELECT id as item_id,\n        title,\n        created_at as _l1_audit_time,\n        current_timestamp as _dim_item_audit_time\n    FROM "2024_melissa_herszage_schema".l1_items as i\n    CROSS JOIN filter_variables fv\n    WHERE i.created_at > last_updated\n    )\n;\n\nDELETE FROM "2024_melissa_herszage_schema".l2_dim_item\nWHERE item_id IN (SELECT item_id FROM staging_dim_item)\n;\n\nINSERT INTO "2024_melissa_herszage_schema".l2_dim_item\n(SELECT * FROM staging_dim_item)\n;\n\nEND TRANSACTION\n;', ())

During handling of the above exception, another exception occurred:

Traceback (most recent call last):
  File "/home/airflow/.local/lib/python3.12/site-packages/airflow/models/taskinstance.py", line 767, in _execute_task
    result = _execute_callable(context=context, **execute_callable_kwargs)
             ^^^^^^^^^^^^^^^^^^^^^^^^^^^^^^^^^^^^^^^^^^^^^^^^^^^^^^^^^^^^^
  File "/home/airflow/.local/lib/python3.12/site-packages/airflow/models/taskinstance.py", line 733, in _execute_callable
    return ExecutionCallableRunner(
           ^^^^^^^^^^^^^^^^^^^^^^^^
  File "/home/airflow/.local/lib/python3.12/site-packages/airflow/utils/operator_helpers.py", line 252, in run
    return self.func(*args, **kwargs)
           ^^^^^^^^^^^^^^^^^^^^^^^^^^
  File "/home/airflow/.local/lib/python3.12/site-packages/airflow/models/baseoperator.py", line 406, in wrapper
    return func(self, *args, **kwargs)
           ^^^^^^^^^^^^^^^^^^^^^^^^^^^
  File "/home/airflow/.local/lib/python3.12/site-packages/airflow/providers/common/sql/operators/sql.py", line 272, in execute
    output = hook.run(
             ^^^^^^^^^
  File "/home/airflow/.local/lib/python3.12/site-packages/airflow/providers/common/sql/hooks/sql.py", line 456, in run
    self._run_command(cur, sql_statement, parameters)
  File "/home/airflow/.local/lib/python3.12/site-packages/airflow/providers/common/sql/hooks/sql.py", line 514, in _run_command
    cur.execute(sql_statement)
  File "/home/airflow/.local/lib/python3.12/site-packages/redshift_connector/cursor.py", line 248, in execute
    raise e
  File "/home/airflow/.local/lib/python3.12/site-packages/redshift_connector/cursor.py", line 241, in execute
    self._c.execute(self, operation, args)
  File "/home/airflow/.local/lib/python3.12/site-packages/redshift_connector/core.py", line 1911, in execute
    self.handle_messages(cursor)
  File "/home/airflow/.local/lib/python3.12/site-packages/redshift_connector/core.py", line 2203, in handle_messages
    raise self.error
redshift_connector.error.ProgrammingError: {'S': 'ERROR', 'C': '42601', 'M': 'cannot insert multiple commands into a prepared statement', 'F': '/home/ec2-user/padb/src/pg/src/backend/tcop/postgres.c', 'L': '4303', 'R': 'exec_parse_message'}
[2024-10-21T03:11:05.240+0000] {taskinstance.py:1225} INFO - Marking task as UP_FOR_RETRY. dag_id=elt, task_id=transform_data.run_dim_item, run_id=manual__2024-10-21T03:09:40.637302+00:00, execution_date=20241021T030940, start_date=20241021T031045, end_date=20241021T031105
[2024-10-21T03:11:05.415+0000] {taskinstance.py:340} INFO - ::group::Post task execution logs
[2024-10-21T03:11:05.440+0000] {standard_task_runner.py:124} ERROR - Failed to execute job 121 for task transform_data.run_dim_item ({'S': 'ERROR', 'C': '42601', 'M': 'cannot insert multiple commands into a prepared statement', 'F': '/home/ec2-user/padb/src/pg/src/backend/tcop/postgres.c', 'L': '4303', 'R': 'exec_parse_message'}; 310)
Traceback (most recent call last):
  File "/home/airflow/.local/lib/python3.12/site-packages/redshift_connector/core.py", line 1830, in execute
    ps = cache["ps"][key]
         ~~~~~~~~~~~^^^^^
KeyError: ('BEGIN TRANSACTION\n;\n\nCREATE TEMPORARY TABLE staging_dim_item AS\n(\nWITH filter_variables AS\n(SELECT COALESCE(MAX(_dim_item_audit_time), \'2024-10-16\'::timestamp) AS last_updated FROM "2024_melissa_herszage_schema".l2_dim_item)\n\n    SELECT id as item_id,\n        title,\n        created_at as _l1_audit_time,\n        current_timestamp as _dim_item_audit_time\n    FROM "2024_melissa_herszage_schema".l1_items as i\n    CROSS JOIN filter_variables fv\n    WHERE i.created_at > last_updated\n    )\n;\n\nDELETE FROM "2024_melissa_herszage_schema".l2_dim_item\nWHERE item_id IN (SELECT item_id FROM staging_dim_item)\n;\n\nINSERT INTO "2024_melissa_herszage_schema".l2_dim_item\n(SELECT * FROM staging_dim_item)\n;\n\nEND TRANSACTION\n;', ())

During handling of the above exception, another exception occurred:

Traceback (most recent call last):
  File "/home/airflow/.local/lib/python3.12/site-packages/airflow/task/task_runner/standard_task_runner.py", line 117, in _start_by_fork
    ret = args.func(args, dag=self.dag)
          ^^^^^^^^^^^^^^^^^^^^^^^^^^^^^
  File "/home/airflow/.local/lib/python3.12/site-packages/airflow/cli/cli_config.py", line 49, in command
    return func(*args, **kwargs)
           ^^^^^^^^^^^^^^^^^^^^^
  File "/home/airflow/.local/lib/python3.12/site-packages/airflow/utils/cli.py", line 115, in wrapper
    return f(*args, **kwargs)
           ^^^^^^^^^^^^^^^^^^
  File "/home/airflow/.local/lib/python3.12/site-packages/airflow/cli/commands/task_command.py", line 483, in task_run
    task_return_code = _run_task_by_selected_method(args, _dag, ti)
                       ^^^^^^^^^^^^^^^^^^^^^^^^^^^^^^^^^^^^^^^^^^^^
  File "/home/airflow/.local/lib/python3.12/site-packages/airflow/cli/commands/task_command.py", line 256, in _run_task_by_selected_method
    return _run_raw_task(args, ti)
           ^^^^^^^^^^^^^^^^^^^^^^^
  File "/home/airflow/.local/lib/python3.12/site-packages/airflow/cli/commands/task_command.py", line 341, in _run_raw_task
    return ti._run_raw_task(
           ^^^^^^^^^^^^^^^^^
  File "/home/airflow/.local/lib/python3.12/site-packages/airflow/utils/session.py", line 97, in wrapper
    return func(*args, session=session, **kwargs)
           ^^^^^^^^^^^^^^^^^^^^^^^^^^^^^^^^^^^^^^
  File "/home/airflow/.local/lib/python3.12/site-packages/airflow/models/taskinstance.py", line 3004, in _run_raw_task
    return _run_raw_task(
           ^^^^^^^^^^^^^^
  File "/home/airflow/.local/lib/python3.12/site-packages/airflow/models/taskinstance.py", line 273, in _run_raw_task
    TaskInstance._execute_task_with_callbacks(
  File "/home/airflow/.local/lib/python3.12/site-packages/airflow/models/taskinstance.py", line 3158, in _execute_task_with_callbacks
    result = self._execute_task(context, task_orig)
             ^^^^^^^^^^^^^^^^^^^^^^^^^^^^^^^^^^^^^^
  File "/home/airflow/.local/lib/python3.12/site-packages/airflow/models/taskinstance.py", line 3182, in _execute_task
    return _execute_task(self, context, task_orig)
           ^^^^^^^^^^^^^^^^^^^^^^^^^^^^^^^^^^^^^^^
  File "/home/airflow/.local/lib/python3.12/site-packages/airflow/models/taskinstance.py", line 767, in _execute_task
    result = _execute_callable(context=context, **execute_callable_kwargs)
             ^^^^^^^^^^^^^^^^^^^^^^^^^^^^^^^^^^^^^^^^^^^^^^^^^^^^^^^^^^^^^
  File "/home/airflow/.local/lib/python3.12/site-packages/airflow/models/taskinstance.py", line 733, in _execute_callable
    return ExecutionCallableRunner(
           ^^^^^^^^^^^^^^^^^^^^^^^^
  File "/home/airflow/.local/lib/python3.12/site-packages/airflow/utils/operator_helpers.py", line 252, in run
    return self.func(*args, **kwargs)
           ^^^^^^^^^^^^^^^^^^^^^^^^^^
  File "/home/airflow/.local/lib/python3.12/site-packages/airflow/models/baseoperator.py", line 406, in wrapper
    return func(self, *args, **kwargs)
           ^^^^^^^^^^^^^^^^^^^^^^^^^^^
  File "/home/airflow/.local/lib/python3.12/site-packages/airflow/providers/common/sql/operators/sql.py", line 272, in execute
    output = hook.run(
             ^^^^^^^^^
  File "/home/airflow/.local/lib/python3.12/site-packages/airflow/providers/common/sql/hooks/sql.py", line 456, in run
    self._run_command(cur, sql_statement, parameters)
  File "/home/airflow/.local/lib/python3.12/site-packages/airflow/providers/common/sql/hooks/sql.py", line 514, in _run_command
    cur.execute(sql_statement)
  File "/home/airflow/.local/lib/python3.12/site-packages/redshift_connector/cursor.py", line 248, in execute
    raise e
  File "/home/airflow/.local/lib/python3.12/site-packages/redshift_connector/cursor.py", line 241, in execute
    self._c.execute(self, operation, args)
  File "/home/airflow/.local/lib/python3.12/site-packages/redshift_connector/core.py", line 1911, in execute
    self.handle_messages(cursor)
  File "/home/airflow/.local/lib/python3.12/site-packages/redshift_connector/core.py", line 2203, in handle_messages
    raise self.error
redshift_connector.error.ProgrammingError: {'S': 'ERROR', 'C': '42601', 'M': 'cannot insert multiple commands into a prepared statement', 'F': '/home/ec2-user/padb/src/pg/src/backend/tcop/postgres.c', 'L': '4303', 'R': 'exec_parse_message'}
[2024-10-21T03:11:05.653+0000] {local_task_job_runner.py:266} INFO - Task exited with return code 1
[2024-10-21T03:11:06.113+0000] {taskinstance.py:3900} INFO - 0 downstream tasks scheduled from follow-on schedule check
[2024-10-21T03:11:06.146+0000] {local_task_job_runner.py:245} INFO - ::endgroup::
