[2024-10-21T03:12:33.924+0000] {local_task_job_runner.py:123} INFO - ::group::Pre task execution logs
[2024-10-21T03:12:33.985+0000] {taskinstance.py:2612} INFO - Dependencies all met for dep_context=non-requeueable deps ti=<TaskInstance: elt.extract_load_data.create_table_items manual__2024-10-21T03:12:26.878284+00:00 [queued]>
[2024-10-21T03:12:33.999+0000] {taskinstance.py:2612} INFO - Dependencies all met for dep_context=requeueable deps ti=<TaskInstance: elt.extract_load_data.create_table_items manual__2024-10-21T03:12:26.878284+00:00 [queued]>
[2024-10-21T03:12:34.001+0000] {taskinstance.py:2865} INFO - Starting attempt 1 of 2
[2024-10-21T03:12:34.026+0000] {taskinstance.py:2888} INFO - Executing <Task(PostgresOperator): extract_load_data.create_table_items> on 2024-10-21 03:12:26.878284+00:00
[2024-10-21T03:12:34.081+0000] {warnings.py:112} WARNING - /home/***/.local/lib/python3.12/site-packages/***/task/task_runner/standard_task_runner.py:70: DeprecationWarning: This process (pid=336) is multi-threaded, use of fork() may lead to deadlocks in the child.
  pid = os.fork()

[2024-10-21T03:12:34.096+0000] {standard_task_runner.py:72} INFO - Started process 340 to run task
[2024-10-21T03:12:34.101+0000] {standard_task_runner.py:104} INFO - Running: ['***', 'tasks', 'run', 'elt', 'extract_load_data.create_table_items', 'manual__2024-10-21T03:12:26.878284+00:00', '--job-id', '126', '--raw', '--subdir', 'DAGS_FOLDER/elt.py', '--cfg-path', '/tmp/tmphy81x4hl']
[2024-10-21T03:12:34.110+0000] {standard_task_runner.py:105} INFO - Job 126: Subtask extract_load_data.create_table_items
[2024-10-21T03:12:46.670+0000] {job.py:229} INFO - Heartbeat recovered after 12.98 seconds
[2024-10-21T03:12:56.788+0000] {task_command.py:467} INFO - Running <TaskInstance: elt.extract_load_data.create_table_items manual__2024-10-21T03:12:26.878284+00:00 [running]> on host 6c3793bbe9c9
[2024-10-21T03:12:57.915+0000] {taskinstance.py:3131} INFO - Exporting env vars: AIRFLOW_CTX_DAG_OWNER='mherszage' AIRFLOW_CTX_DAG_ID='elt' AIRFLOW_CTX_TASK_ID='extract_load_data.create_table_items' AIRFLOW_CTX_EXECUTION_DATE='2024-10-21T03:12:26.878284+00:00' AIRFLOW_CTX_TRY_NUMBER='1' AIRFLOW_CTX_DAG_RUN_ID='manual__2024-10-21T03:12:26.878284+00:00'
[2024-10-21T03:12:57.931+0000] {taskinstance.py:731} INFO - ::endgroup::
[2024-10-21T03:12:58.169+0000] {sql.py:266} INFO - Executing: CREATE TABLE IF NOT EXISTS "2024_melissa_herszage_schema".l1_items
(
    id    varchar(256),
    title varchar(256),
    created_at timestamp
);
[2024-10-21T03:12:58.212+0000] {base.py:84} INFO - Retrieving connection 'redshift_default'
[2024-10-21T03:12:59.320+0000] {base.py:84} INFO - Retrieving connection 'redshift_default'
[2024-10-21T03:13:01.078+0000] {job.py:229} INFO - Heartbeat recovered after 14.66 seconds
[2024-10-21T03:13:14.746+0000] {taskinstance.py:3310} ERROR - Task failed with exception
Traceback (most recent call last):
  File "/home/airflow/.local/lib/python3.12/site-packages/redshift_connector/core.py", line 632, in __init__
    hostport: typing.Tuple[str, int] = Connection.__get_host_address_info(host, port)
                                       ^^^^^^^^^^^^^^^^^^^^^^^^^^^^^^^^^^^^^^^^^^^^^^
  File "/home/airflow/.local/lib/python3.12/site-packages/redshift_connector/core.py", line 404, in __get_host_address_info
    response = socket.getaddrinfo(host=host, port=port, family=socket.AF_INET)
               ^^^^^^^^^^^^^^^^^^^^^^^^^^^^^^^^^^^^^^^^^^^^^^^^^^^^^^^^^^^^^^^
  File "/usr/local/lib/python3.12/socket.py", line 976, in getaddrinfo
    for res in _socket.getaddrinfo(host, port, family, type, proto, flags):
               ^^^^^^^^^^^^^^^^^^^^^^^^^^^^^^^^^^^^^^^^^^^^^^^^^^^^^^^^^^^
socket.gaierror: [Errno -3] Temporary failure in name resolution

During handling of the above exception, another exception occurred:

Traceback (most recent call last):
  File "/home/airflow/.local/lib/python3.12/site-packages/airflow/models/taskinstance.py", line 767, in _execute_task
    result = _execute_callable(context=context, **execute_callable_kwargs)
             ^^^^^^^^^^^^^^^^^^^^^^^^^^^^^^^^^^^^^^^^^^^^^^^^^^^^^^^^^^^^^
  File "/home/airflow/.local/lib/python3.12/site-packages/airflow/models/taskinstance.py", line 733, in _execute_callable
    return ExecutionCallableRunner(
           ^^^^^^^^^^^^^^^^^^^^^^^^
  File "/home/airflow/.local/lib/python3.12/site-packages/airflow/utils/operator_helpers.py", line 252, in run
    return self.func(*args, **kwargs)
           ^^^^^^^^^^^^^^^^^^^^^^^^^^
  File "/home/airflow/.local/lib/python3.12/site-packages/airflow/models/baseoperator.py", line 406, in wrapper
    return func(self, *args, **kwargs)
           ^^^^^^^^^^^^^^^^^^^^^^^^^^^
  File "/home/airflow/.local/lib/python3.12/site-packages/airflow/providers/common/sql/operators/sql.py", line 272, in execute
    output = hook.run(
             ^^^^^^^^^
  File "/home/airflow/.local/lib/python3.12/site-packages/airflow/providers/common/sql/hooks/sql.py", line 452, in run
    with self._create_autocommit_connection(autocommit) as conn:
         ^^^^^^^^^^^^^^^^^^^^^^^^^^^^^^^^^^^^^^^^^^^^^^
  File "/usr/local/lib/python3.12/contextlib.py", line 137, in __enter__
    return next(self.gen)
           ^^^^^^^^^^^^^^
  File "/home/airflow/.local/lib/python3.12/site-packages/airflow/providers/common/sql/hooks/sql.py", line 574, in _create_autocommit_connection
    with closing(self.get_conn()) as conn:
                 ^^^^^^^^^^^^^^^
  File "/home/airflow/.local/lib/python3.12/site-packages/airflow/providers/amazon/aws/hooks/redshift_sql.py", line 208, in get_conn
    return redshift_connector.connect(**conn_kwargs)
           ^^^^^^^^^^^^^^^^^^^^^^^^^^^^^^^^^^^^^^^^^
  File "/home/airflow/.local/lib/python3.12/site-packages/redshift_connector/__init__.py", line 394, in connect
    return Connection(
           ^^^^^^^^^^^
  File "/home/airflow/.local/lib/python3.12/site-packages/redshift_connector/core.py", line 698, in __init__
    raise InterfaceError("communication error", e)
redshift_connector.error.InterfaceError: ('communication error', gaierror(-3, 'Temporary failure in name resolution'))
[2024-10-21T03:13:17.415+0000] {taskinstance.py:1225} INFO - Marking task as UP_FOR_RETRY. dag_id=elt, task_id=extract_load_data.create_table_items, run_id=manual__2024-10-21T03:12:26.878284+00:00, execution_date=20241021T031226, start_date=20241021T031233, end_date=20241021T031317
[2024-10-21T03:13:17.430+0000] {job.py:229} INFO - Heartbeat recovered after 16.40 seconds
[2024-10-21T03:13:17.562+0000] {taskinstance.py:340} INFO - ::group::Post task execution logs
[2024-10-21T03:13:17.575+0000] {standard_task_runner.py:124} ERROR - Failed to execute job 126 for task extract_load_data.create_table_items (('communication error', gaierror(-3, 'Temporary failure in name resolution')); 340)
Traceback (most recent call last):
  File "/home/airflow/.local/lib/python3.12/site-packages/redshift_connector/core.py", line 632, in __init__
    hostport: typing.Tuple[str, int] = Connection.__get_host_address_info(host, port)
                                       ^^^^^^^^^^^^^^^^^^^^^^^^^^^^^^^^^^^^^^^^^^^^^^
  File "/home/airflow/.local/lib/python3.12/site-packages/redshift_connector/core.py", line 404, in __get_host_address_info
    response = socket.getaddrinfo(host=host, port=port, family=socket.AF_INET)
               ^^^^^^^^^^^^^^^^^^^^^^^^^^^^^^^^^^^^^^^^^^^^^^^^^^^^^^^^^^^^^^^
  File "/usr/local/lib/python3.12/socket.py", line 976, in getaddrinfo
    for res in _socket.getaddrinfo(host, port, family, type, proto, flags):
               ^^^^^^^^^^^^^^^^^^^^^^^^^^^^^^^^^^^^^^^^^^^^^^^^^^^^^^^^^^^
socket.gaierror: [Errno -3] Temporary failure in name resolution

During handling of the above exception, another exception occurred:

Traceback (most recent call last):
  File "/home/airflow/.local/lib/python3.12/site-packages/airflow/task/task_runner/standard_task_runner.py", line 117, in _start_by_fork
    ret = args.func(args, dag=self.dag)
          ^^^^^^^^^^^^^^^^^^^^^^^^^^^^^
  File "/home/airflow/.local/lib/python3.12/site-packages/airflow/cli/cli_config.py", line 49, in command
    return func(*args, **kwargs)
           ^^^^^^^^^^^^^^^^^^^^^
  File "/home/airflow/.local/lib/python3.12/site-packages/airflow/utils/cli.py", line 115, in wrapper
    return f(*args, **kwargs)
           ^^^^^^^^^^^^^^^^^^
  File "/home/airflow/.local/lib/python3.12/site-packages/airflow/cli/commands/task_command.py", line 483, in task_run
    task_return_code = _run_task_by_selected_method(args, _dag, ti)
                       ^^^^^^^^^^^^^^^^^^^^^^^^^^^^^^^^^^^^^^^^^^^^
  File "/home/airflow/.local/lib/python3.12/site-packages/airflow/cli/commands/task_command.py", line 256, in _run_task_by_selected_method
    return _run_raw_task(args, ti)
           ^^^^^^^^^^^^^^^^^^^^^^^
  File "/home/airflow/.local/lib/python3.12/site-packages/airflow/cli/commands/task_command.py", line 341, in _run_raw_task
    return ti._run_raw_task(
           ^^^^^^^^^^^^^^^^^
  File "/home/airflow/.local/lib/python3.12/site-packages/airflow/utils/session.py", line 97, in wrapper
    return func(*args, session=session, **kwargs)
           ^^^^^^^^^^^^^^^^^^^^^^^^^^^^^^^^^^^^^^
  File "/home/airflow/.local/lib/python3.12/site-packages/airflow/models/taskinstance.py", line 3004, in _run_raw_task
    return _run_raw_task(
           ^^^^^^^^^^^^^^
  File "/home/airflow/.local/lib/python3.12/site-packages/airflow/models/taskinstance.py", line 273, in _run_raw_task
    TaskInstance._execute_task_with_callbacks(
  File "/home/airflow/.local/lib/python3.12/site-packages/airflow/models/taskinstance.py", line 3158, in _execute_task_with_callbacks
    result = self._execute_task(context, task_orig)
             ^^^^^^^^^^^^^^^^^^^^^^^^^^^^^^^^^^^^^^
  File "/home/airflow/.local/lib/python3.12/site-packages/airflow/models/taskinstance.py", line 3182, in _execute_task
    return _execute_task(self, context, task_orig)
           ^^^^^^^^^^^^^^^^^^^^^^^^^^^^^^^^^^^^^^^
  File "/home/airflow/.local/lib/python3.12/site-packages/airflow/models/taskinstance.py", line 767, in _execute_task
    result = _execute_callable(context=context, **execute_callable_kwargs)
             ^^^^^^^^^^^^^^^^^^^^^^^^^^^^^^^^^^^^^^^^^^^^^^^^^^^^^^^^^^^^^
  File "/home/airflow/.local/lib/python3.12/site-packages/airflow/models/taskinstance.py", line 733, in _execute_callable
    return ExecutionCallableRunner(
           ^^^^^^^^^^^^^^^^^^^^^^^^
  File "/home/airflow/.local/lib/python3.12/site-packages/airflow/utils/operator_helpers.py", line 252, in run
    return self.func(*args, **kwargs)
           ^^^^^^^^^^^^^^^^^^^^^^^^^^
  File "/home/airflow/.local/lib/python3.12/site-packages/airflow/models/baseoperator.py", line 406, in wrapper
    return func(self, *args, **kwargs)
           ^^^^^^^^^^^^^^^^^^^^^^^^^^^
  File "/home/airflow/.local/lib/python3.12/site-packages/airflow/providers/common/sql/operators/sql.py", line 272, in execute
    output = hook.run(
             ^^^^^^^^^
  File "/home/airflow/.local/lib/python3.12/site-packages/airflow/providers/common/sql/hooks/sql.py", line 452, in run
    with self._create_autocommit_connection(autocommit) as conn:
         ^^^^^^^^^^^^^^^^^^^^^^^^^^^^^^^^^^^^^^^^^^^^^^
  File "/usr/local/lib/python3.12/contextlib.py", line 137, in __enter__
    return next(self.gen)
           ^^^^^^^^^^^^^^
  File "/home/airflow/.local/lib/python3.12/site-packages/airflow/providers/common/sql/hooks/sql.py", line 574, in _create_autocommit_connection
    with closing(self.get_conn()) as conn:
                 ^^^^^^^^^^^^^^^
  File "/home/airflow/.local/lib/python3.12/site-packages/airflow/providers/amazon/aws/hooks/redshift_sql.py", line 208, in get_conn
    return redshift_connector.connect(**conn_kwargs)
           ^^^^^^^^^^^^^^^^^^^^^^^^^^^^^^^^^^^^^^^^^
  File "/home/airflow/.local/lib/python3.12/site-packages/redshift_connector/__init__.py", line 394, in connect
    return Connection(
           ^^^^^^^^^^^
  File "/home/airflow/.local/lib/python3.12/site-packages/redshift_connector/core.py", line 698, in __init__
    raise InterfaceError("communication error", e)
redshift_connector.error.InterfaceError: ('communication error', gaierror(-3, 'Temporary failure in name resolution'))
[2024-10-21T03:13:17.642+0000] {local_task_job_runner.py:266} INFO - Task exited with return code 1
[2024-10-21T03:13:17.698+0000] {warnings.py:112} WARNING - /home/***/.local/lib/python3.12/site-packages/***/models/baseoperator.py:1378: AirflowProviderDeprecationWarning: Call to deprecated class PostgresOperator. (Please use `***.providers.common.sql.operators.sql.SQLExecuteQueryOperator`.Also, you can provide `hook_params={'schema': <database>}`.)
  result = cls.__new__(cls)

[2024-10-21T03:13:17.740+0000] {taskinstance.py:3900} INFO - 0 downstream tasks scheduled from follow-on schedule check
[2024-10-21T03:13:17.747+0000] {local_task_job_runner.py:245} INFO - ::endgroup::
