[2024-10-15T03:59:14.558+0000] {local_task_job_runner.py:123} INFO - ::group::Pre task execution logs
[2024-10-15T03:59:14.573+0000] {taskinstance.py:2612} INFO - Dependencies all met for dep_context=non-requeueable deps ti=<TaskInstance: insert_items.inserts.insert_items manual__2024-10-15T03:58:05.403191+00:00 [queued]>
[2024-10-15T03:59:14.577+0000] {taskinstance.py:2612} INFO - Dependencies all met for dep_context=requeueable deps ti=<TaskInstance: insert_items.inserts.insert_items manual__2024-10-15T03:58:05.403191+00:00 [queued]>
[2024-10-15T03:59:14.578+0000] {taskinstance.py:2865} INFO - Starting attempt 2 of 2
[2024-10-15T03:59:14.585+0000] {taskinstance.py:2888} INFO - Executing <Task(PythonOperator): inserts.insert_items> on 2024-10-15 03:58:05.403191+00:00
[2024-10-15T03:59:14.598+0000] {warnings.py:112} WARNING - /home/***/.local/lib/python3.12/site-packages/***/task/task_runner/standard_task_runner.py:70: DeprecationWarning: This process (pid=88) is multi-threaded, use of fork() may lead to deadlocks in the child.
  pid = os.fork()

[2024-10-15T03:59:14.612+0000] {standard_task_runner.py:72} INFO - Started process 90 to run task
[2024-10-15T03:59:14.614+0000] {standard_task_runner.py:104} INFO - Running: ['***', 'tasks', 'run', 'insert_items', 'inserts.insert_items', 'manual__2024-10-15T03:58:05.403191+00:00', '--job-id', '8', '--raw', '--subdir', 'DAGS_FOLDER/insert_items.py', '--cfg-path', '/tmp/tmpvn3fj0f1']
[2024-10-15T03:59:14.620+0000] {standard_task_runner.py:105} INFO - Job 8: Subtask inserts.insert_items
[2024-10-15T03:59:14.659+0000] {task_command.py:467} INFO - Running <TaskInstance: insert_items.inserts.insert_items manual__2024-10-15T03:58:05.403191+00:00 [running]> on host 9ba62a308c22
[2024-10-15T03:59:15.408+0000] {taskinstance.py:3131} INFO - Exporting env vars: AIRFLOW_CTX_DAG_OWNER='mherszage' AIRFLOW_CTX_DAG_ID='insert_items' AIRFLOW_CTX_TASK_ID='inserts.insert_items' AIRFLOW_CTX_EXECUTION_DATE='2024-10-15T03:58:05.403191+00:00' AIRFLOW_CTX_TRY_NUMBER='2' AIRFLOW_CTX_DAG_RUN_ID='manual__2024-10-15T03:58:05.403191+00:00'
[2024-10-15T03:59:15.410+0000] {taskinstance.py:731} INFO - ::endgroup::
[2024-10-15T03:59:17.281+0000] {taskinstance.py:3310} ERROR - Task failed with exception
Traceback (most recent call last):
  File "/home/airflow/.local/lib/python3.12/site-packages/airflow/models/taskinstance.py", line 767, in _execute_task
    result = _execute_callable(context=context, **execute_callable_kwargs)
             ^^^^^^^^^^^^^^^^^^^^^^^^^^^^^^^^^^^^^^^^^^^^^^^^^^^^^^^^^^^^^
  File "/home/airflow/.local/lib/python3.12/site-packages/airflow/models/taskinstance.py", line 733, in _execute_callable
    return ExecutionCallableRunner(
           ^^^^^^^^^^^^^^^^^^^^^^^^
  File "/home/airflow/.local/lib/python3.12/site-packages/airflow/utils/operator_helpers.py", line 252, in run
    return self.func(*args, **kwargs)
           ^^^^^^^^^^^^^^^^^^^^^^^^^^
  File "/home/airflow/.local/lib/python3.12/site-packages/airflow/models/baseoperator.py", line 406, in wrapper
    return func(self, *args, **kwargs)
           ^^^^^^^^^^^^^^^^^^^^^^^^^^^
  File "/home/airflow/.local/lib/python3.12/site-packages/airflow/operators/python.py", line 238, in execute
    return_value = self.execute_callable()
                   ^^^^^^^^^^^^^^^^^^^^^^^
  File "/home/airflow/.local/lib/python3.12/site-packages/airflow/operators/python.py", line 256, in execute_callable
    return runner.run(*self.op_args, **self.op_kwargs)
           ^^^^^^^^^^^^^^^^^^^^^^^^^^^^^^^^^^^^^^^^^^^
  File "/home/airflow/.local/lib/python3.12/site-packages/airflow/utils/operator_helpers.py", line 252, in run
    return self.func(*args, **kwargs)
           ^^^^^^^^^^^^^^^^^^^^^^^^^^
  File "/opt/airflow/dags/python_files/items/items.py", line 29, in insert_items
    conn = psycopg2.connect(
           ^^^^^^^^
NameError: name 'psycopg2' is not defined
[2024-10-15T03:59:17.316+0000] {taskinstance.py:1225} INFO - Marking task as FAILED. dag_id=insert_items, task_id=inserts.insert_items, run_id=manual__2024-10-15T03:58:05.403191+00:00, execution_date=20241015T035805, start_date=20241015T035914, end_date=20241015T035917
[2024-10-15T03:59:17.347+0000] {taskinstance.py:340} INFO - ::group::Post task execution logs
[2024-10-15T03:59:17.348+0000] {standard_task_runner.py:124} ERROR - Failed to execute job 8 for task inserts.insert_items (name 'psycopg2' is not defined; 90)
Traceback (most recent call last):
  File "/home/airflow/.local/lib/python3.12/site-packages/airflow/task/task_runner/standard_task_runner.py", line 117, in _start_by_fork
    ret = args.func(args, dag=self.dag)
          ^^^^^^^^^^^^^^^^^^^^^^^^^^^^^
  File "/home/airflow/.local/lib/python3.12/site-packages/airflow/cli/cli_config.py", line 49, in command
    return func(*args, **kwargs)
           ^^^^^^^^^^^^^^^^^^^^^
  File "/home/airflow/.local/lib/python3.12/site-packages/airflow/utils/cli.py", line 115, in wrapper
    return f(*args, **kwargs)
           ^^^^^^^^^^^^^^^^^^
  File "/home/airflow/.local/lib/python3.12/site-packages/airflow/cli/commands/task_command.py", line 483, in task_run
    task_return_code = _run_task_by_selected_method(args, _dag, ti)
                       ^^^^^^^^^^^^^^^^^^^^^^^^^^^^^^^^^^^^^^^^^^^^
  File "/home/airflow/.local/lib/python3.12/site-packages/airflow/cli/commands/task_command.py", line 256, in _run_task_by_selected_method
    return _run_raw_task(args, ti)
           ^^^^^^^^^^^^^^^^^^^^^^^
  File "/home/airflow/.local/lib/python3.12/site-packages/airflow/cli/commands/task_command.py", line 341, in _run_raw_task
    return ti._run_raw_task(
           ^^^^^^^^^^^^^^^^^
  File "/home/airflow/.local/lib/python3.12/site-packages/airflow/utils/session.py", line 97, in wrapper
    return func(*args, session=session, **kwargs)
           ^^^^^^^^^^^^^^^^^^^^^^^^^^^^^^^^^^^^^^
  File "/home/airflow/.local/lib/python3.12/site-packages/airflow/models/taskinstance.py", line 3004, in _run_raw_task
    return _run_raw_task(
           ^^^^^^^^^^^^^^
  File "/home/airflow/.local/lib/python3.12/site-packages/airflow/models/taskinstance.py", line 273, in _run_raw_task
    TaskInstance._execute_task_with_callbacks(
  File "/home/airflow/.local/lib/python3.12/site-packages/airflow/models/taskinstance.py", line 3158, in _execute_task_with_callbacks
    result = self._execute_task(context, task_orig)
             ^^^^^^^^^^^^^^^^^^^^^^^^^^^^^^^^^^^^^^
  File "/home/airflow/.local/lib/python3.12/site-packages/airflow/models/taskinstance.py", line 3182, in _execute_task
    return _execute_task(self, context, task_orig)
           ^^^^^^^^^^^^^^^^^^^^^^^^^^^^^^^^^^^^^^^
  File "/home/airflow/.local/lib/python3.12/site-packages/airflow/models/taskinstance.py", line 767, in _execute_task
    result = _execute_callable(context=context, **execute_callable_kwargs)
             ^^^^^^^^^^^^^^^^^^^^^^^^^^^^^^^^^^^^^^^^^^^^^^^^^^^^^^^^^^^^^
  File "/home/airflow/.local/lib/python3.12/site-packages/airflow/models/taskinstance.py", line 733, in _execute_callable
    return ExecutionCallableRunner(
           ^^^^^^^^^^^^^^^^^^^^^^^^
  File "/home/airflow/.local/lib/python3.12/site-packages/airflow/utils/operator_helpers.py", line 252, in run
    return self.func(*args, **kwargs)
           ^^^^^^^^^^^^^^^^^^^^^^^^^^
  File "/home/airflow/.local/lib/python3.12/site-packages/airflow/models/baseoperator.py", line 406, in wrapper
    return func(self, *args, **kwargs)
           ^^^^^^^^^^^^^^^^^^^^^^^^^^^
  File "/home/airflow/.local/lib/python3.12/site-packages/airflow/operators/python.py", line 238, in execute
    return_value = self.execute_callable()
                   ^^^^^^^^^^^^^^^^^^^^^^^
  File "/home/airflow/.local/lib/python3.12/site-packages/airflow/operators/python.py", line 256, in execute_callable
    return runner.run(*self.op_args, **self.op_kwargs)
           ^^^^^^^^^^^^^^^^^^^^^^^^^^^^^^^^^^^^^^^^^^^
  File "/home/airflow/.local/lib/python3.12/site-packages/airflow/utils/operator_helpers.py", line 252, in run
    return self.func(*args, **kwargs)
           ^^^^^^^^^^^^^^^^^^^^^^^^^^
  File "/opt/airflow/dags/python_files/items/items.py", line 29, in insert_items
    conn = psycopg2.connect(
           ^^^^^^^^
NameError: name 'psycopg2' is not defined
[2024-10-15T03:59:17.392+0000] {local_task_job_runner.py:266} INFO - Task exited with return code 1
[2024-10-15T03:59:17.476+0000] {taskinstance.py:3900} INFO - 0 downstream tasks scheduled from follow-on schedule check
[2024-10-15T03:59:17.479+0000] {local_task_job_runner.py:245} INFO - ::endgroup::
