[2024-10-18T05:15:33.961+0000] {local_task_job_runner.py:123} INFO - ::group::Pre task execution logs
[2024-10-18T05:15:33.969+0000] {taskinstance.py:2612} INFO - Dependencies all met for dep_context=non-requeueable deps ti=<TaskInstance: elt.transform_data.l2_dim_item manual__2024-10-18T05:13:53.719759+00:00 [queued]>
[2024-10-18T05:15:33.973+0000] {taskinstance.py:2612} INFO - Dependencies all met for dep_context=requeueable deps ti=<TaskInstance: elt.transform_data.l2_dim_item manual__2024-10-18T05:13:53.719759+00:00 [queued]>
[2024-10-18T05:15:33.974+0000] {taskinstance.py:2865} INFO - Starting attempt 2 of 2
[2024-10-18T05:15:33.979+0000] {taskinstance.py:2888} INFO - Executing <Task(PostgresOperator): transform_data.l2_dim_item> on 2024-10-18 05:13:53.719759+00:00
[2024-10-18T05:15:33.983+0000] {warnings.py:112} WARNING - /home/***/.local/lib/python3.12/site-packages/***/task/task_runner/standard_task_runner.py:70: DeprecationWarning: This process (pid=2024) is multi-threaded, use of fork() may lead to deadlocks in the child.
  pid = os.fork()

[2024-10-18T05:15:33.984+0000] {standard_task_runner.py:72} INFO - Started process 2026 to run task
[2024-10-18T05:15:33.984+0000] {standard_task_runner.py:104} INFO - Running: ['***', 'tasks', 'run', 'elt', 'transform_data.l2_dim_item', 'manual__2024-10-18T05:13:53.719759+00:00', '--job-id', '201', '--raw', '--subdir', 'DAGS_FOLDER/elt.py', '--cfg-path', '/tmp/tmp2mas6k0r']
[2024-10-18T05:15:33.986+0000] {standard_task_runner.py:105} INFO - Job 201: Subtask transform_data.l2_dim_item
[2024-10-18T05:15:34.364+0000] {task_command.py:467} INFO - Running <TaskInstance: elt.transform_data.l2_dim_item manual__2024-10-18T05:13:53.719759+00:00 [running]> on host a414d3516fe8
[2024-10-18T05:15:34.497+0000] {taskinstance.py:3131} INFO - Exporting env vars: AIRFLOW_CTX_DAG_OWNER='mherszage' AIRFLOW_CTX_DAG_ID='elt' AIRFLOW_CTX_TASK_ID='transform_data.l2_dim_item' AIRFLOW_CTX_EXECUTION_DATE='2024-10-18T05:13:53.719759+00:00' AIRFLOW_CTX_TRY_NUMBER='2' AIRFLOW_CTX_DAG_RUN_ID='manual__2024-10-18T05:13:53.719759+00:00'
[2024-10-18T05:15:34.502+0000] {taskinstance.py:731} INFO - ::endgroup::
[2024-10-18T05:15:34.537+0000] {sql.py:266} INFO - Executing: BEGIN TRANSACTION
;

CREATE TEMPORARY TABLE staging_dim_item AS
(
WITH filter_variables AS
(SELECT COALESCE(MAX(_dim_item_audit_time), '2024-10-16'::timestamp) AS last_updated FROM "2024_melissa_herszage_schema".l2_dim_item)

    SELECT id as item_id,
        title,
        created_at as _l1_audit_time,
        current_timestamp as _dim_item_audit_time
    FROM "2024_melissa_herszage_schema".l1_items as i
    CROSS JOIN filter_variables fv
    WHERE i.updated_at > last_updated
    )
;

DELETE FROM "2024_melissa_herszage_schema".l2_dim_item
WHERE item_id IN (SELECT item_id FROM staging_dim_item)
;

INSERT INTO "2024_melissa_herszage_schema".l2_dim_item
(SELECT * FROM staging_dim_item)
;

END TRANSACTION
;
[2024-10-18T05:15:34.548+0000] {base.py:84} INFO - Retrieving connection 'redshift_default'
[2024-10-18T05:15:34.556+0000] {base.py:84} INFO - Retrieving connection 'redshift_default'
[2024-10-18T05:15:35.806+0000] {sql.py:509} INFO - Running statement: BEGIN TRANSACTION
;

CREATE TEMPORARY TABLE staging_dim_item AS
(
WITH filter_variables AS
(SELECT COALESCE(MAX(_dim_item_audit_time), '2024-10-16'::timestamp) AS last_updated FROM "2024_melissa_herszage_schema".l2_dim_item)

    SELECT id as item_id,
        title,
        created_at as _l1_audit_time,
        current_timestamp as _dim_item_audit_time
    FROM "2024_melissa_herszage_schema".l1_items as i
    CROSS JOIN filter_variables fv
    WHERE i.updated_at > last_updated
    )
;

DELETE FROM "2024_melissa_herszage_schema".l2_dim_item
WHERE item_id IN (SELECT item_id FROM staging_dim_item)
;

INSERT INTO "2024_melissa_herszage_schema".l2_dim_item
(SELECT * FROM staging_dim_item)
;

END TRANSACTION
;, parameters: None
[2024-10-18T05:15:36.152+0000] {taskinstance.py:3310} ERROR - Task failed with exception
Traceback (most recent call last):
  File "/home/airflow/.local/lib/python3.12/site-packages/airflow/models/taskinstance.py", line 767, in _execute_task
    result = _execute_callable(context=context, **execute_callable_kwargs)
             ^^^^^^^^^^^^^^^^^^^^^^^^^^^^^^^^^^^^^^^^^^^^^^^^^^^^^^^^^^^^^
  File "/home/airflow/.local/lib/python3.12/site-packages/airflow/models/taskinstance.py", line 733, in _execute_callable
    return ExecutionCallableRunner(
           ^^^^^^^^^^^^^^^^^^^^^^^^
  File "/home/airflow/.local/lib/python3.12/site-packages/airflow/utils/operator_helpers.py", line 252, in run
    return self.func(*args, **kwargs)
           ^^^^^^^^^^^^^^^^^^^^^^^^^^
  File "/home/airflow/.local/lib/python3.12/site-packages/airflow/models/baseoperator.py", line 406, in wrapper
    return func(self, *args, **kwargs)
           ^^^^^^^^^^^^^^^^^^^^^^^^^^^
  File "/home/airflow/.local/lib/python3.12/site-packages/airflow/providers/common/sql/operators/sql.py", line 272, in execute
    output = hook.run(
             ^^^^^^^^^
  File "/home/airflow/.local/lib/python3.12/site-packages/airflow/providers/common/sql/hooks/sql.py", line 456, in run
    self._run_command(cur, sql_statement, parameters)
  File "/home/airflow/.local/lib/python3.12/site-packages/airflow/providers/common/sql/hooks/sql.py", line 514, in _run_command
    cur.execute(sql_statement)
psycopg2.errors.UndefinedColumn: column i.updated_at does not exist

[2024-10-18T05:15:36.177+0000] {taskinstance.py:1225} INFO - Marking task as FAILED. dag_id=elt, task_id=transform_data.l2_dim_item, run_id=manual__2024-10-18T05:13:53.719759+00:00, execution_date=20241018T051353, start_date=20241018T051533, end_date=20241018T051536
[2024-10-18T05:15:36.196+0000] {taskinstance.py:340} INFO - ::group::Post task execution logs
[2024-10-18T05:15:36.197+0000] {standard_task_runner.py:124} ERROR - Failed to execute job 201 for task transform_data.l2_dim_item (column i.updated_at does not exist
; 2026)
Traceback (most recent call last):
  File "/home/airflow/.local/lib/python3.12/site-packages/airflow/task/task_runner/standard_task_runner.py", line 117, in _start_by_fork
    ret = args.func(args, dag=self.dag)
          ^^^^^^^^^^^^^^^^^^^^^^^^^^^^^
  File "/home/airflow/.local/lib/python3.12/site-packages/airflow/cli/cli_config.py", line 49, in command
    return func(*args, **kwargs)
           ^^^^^^^^^^^^^^^^^^^^^
  File "/home/airflow/.local/lib/python3.12/site-packages/airflow/utils/cli.py", line 115, in wrapper
    return f(*args, **kwargs)
           ^^^^^^^^^^^^^^^^^^
  File "/home/airflow/.local/lib/python3.12/site-packages/airflow/cli/commands/task_command.py", line 483, in task_run
    task_return_code = _run_task_by_selected_method(args, _dag, ti)
                       ^^^^^^^^^^^^^^^^^^^^^^^^^^^^^^^^^^^^^^^^^^^^
  File "/home/airflow/.local/lib/python3.12/site-packages/airflow/cli/commands/task_command.py", line 256, in _run_task_by_selected_method
    return _run_raw_task(args, ti)
           ^^^^^^^^^^^^^^^^^^^^^^^
  File "/home/airflow/.local/lib/python3.12/site-packages/airflow/cli/commands/task_command.py", line 341, in _run_raw_task
    return ti._run_raw_task(
           ^^^^^^^^^^^^^^^^^
  File "/home/airflow/.local/lib/python3.12/site-packages/airflow/utils/session.py", line 97, in wrapper
    return func(*args, session=session, **kwargs)
           ^^^^^^^^^^^^^^^^^^^^^^^^^^^^^^^^^^^^^^
  File "/home/airflow/.local/lib/python3.12/site-packages/airflow/models/taskinstance.py", line 3004, in _run_raw_task
    return _run_raw_task(
           ^^^^^^^^^^^^^^
  File "/home/airflow/.local/lib/python3.12/site-packages/airflow/models/taskinstance.py", line 273, in _run_raw_task
    TaskInstance._execute_task_with_callbacks(
  File "/home/airflow/.local/lib/python3.12/site-packages/airflow/models/taskinstance.py", line 3158, in _execute_task_with_callbacks
    result = self._execute_task(context, task_orig)
             ^^^^^^^^^^^^^^^^^^^^^^^^^^^^^^^^^^^^^^
  File "/home/airflow/.local/lib/python3.12/site-packages/airflow/models/taskinstance.py", line 3182, in _execute_task
    return _execute_task(self, context, task_orig)
           ^^^^^^^^^^^^^^^^^^^^^^^^^^^^^^^^^^^^^^^
  File "/home/airflow/.local/lib/python3.12/site-packages/airflow/models/taskinstance.py", line 767, in _execute_task
    result = _execute_callable(context=context, **execute_callable_kwargs)
             ^^^^^^^^^^^^^^^^^^^^^^^^^^^^^^^^^^^^^^^^^^^^^^^^^^^^^^^^^^^^^
  File "/home/airflow/.local/lib/python3.12/site-packages/airflow/models/taskinstance.py", line 733, in _execute_callable
    return ExecutionCallableRunner(
           ^^^^^^^^^^^^^^^^^^^^^^^^
  File "/home/airflow/.local/lib/python3.12/site-packages/airflow/utils/operator_helpers.py", line 252, in run
    return self.func(*args, **kwargs)
           ^^^^^^^^^^^^^^^^^^^^^^^^^^
  File "/home/airflow/.local/lib/python3.12/site-packages/airflow/models/baseoperator.py", line 406, in wrapper
    return func(self, *args, **kwargs)
           ^^^^^^^^^^^^^^^^^^^^^^^^^^^
  File "/home/airflow/.local/lib/python3.12/site-packages/airflow/providers/common/sql/operators/sql.py", line 272, in execute
    output = hook.run(
             ^^^^^^^^^
  File "/home/airflow/.local/lib/python3.12/site-packages/airflow/providers/common/sql/hooks/sql.py", line 456, in run
    self._run_command(cur, sql_statement, parameters)
  File "/home/airflow/.local/lib/python3.12/site-packages/airflow/providers/common/sql/hooks/sql.py", line 514, in _run_command
    cur.execute(sql_statement)
psycopg2.errors.UndefinedColumn: column i.updated_at does not exist

[2024-10-18T05:15:36.235+0000] {local_task_job_runner.py:266} INFO - Task exited with return code 1
[2024-10-18T05:15:36.271+0000] {taskinstance.py:3900} INFO - 0 downstream tasks scheduled from follow-on schedule check
[2024-10-18T05:15:36.272+0000] {local_task_job_runner.py:245} INFO - ::endgroup::
