[2024-10-21T02:45:12.325+0000] {local_task_job_runner.py:123} INFO - ::group::Pre task execution logs
[2024-10-21T02:45:12.340+0000] {taskinstance.py:2612} INFO - Dependencies all met for dep_context=non-requeueable deps ti=<TaskInstance: elt.transform_data.run_fact_items_information manual__2024-10-21T02:43:24.311342+00:00 [queued]>
[2024-10-21T02:45:12.348+0000] {taskinstance.py:2612} INFO - Dependencies all met for dep_context=requeueable deps ti=<TaskInstance: elt.transform_data.run_fact_items_information manual__2024-10-21T02:43:24.311342+00:00 [queued]>
[2024-10-21T02:45:12.348+0000] {taskinstance.py:2865} INFO - Starting attempt 2 of 2
[2024-10-21T02:45:12.358+0000] {taskinstance.py:2888} INFO - Executing <Task(PostgresOperator): transform_data.run_fact_items_information> on 2024-10-21 02:43:24.311342+00:00
[2024-10-21T02:45:12.379+0000] {warnings.py:112} WARNING - /home/***/.local/lib/python3.12/site-packages/***/task/task_runner/standard_task_runner.py:70: DeprecationWarning: This process (pid=259) is multi-threaded, use of fork() may lead to deadlocks in the child.
  pid = os.fork()

[2024-10-21T02:45:12.381+0000] {standard_task_runner.py:72} INFO - Started process 264 to run task
[2024-10-21T02:45:12.386+0000] {standard_task_runner.py:104} INFO - Running: ['***', 'tasks', 'run', 'elt', 'transform_data.run_fact_items_information', 'manual__2024-10-21T02:43:24.311342+00:00', '--job-id', '92', '--raw', '--subdir', 'DAGS_FOLDER/elt.py', '--cfg-path', '/tmp/tmppglhtn5i']
[2024-10-21T02:45:12.389+0000] {standard_task_runner.py:105} INFO - Job 92: Subtask transform_data.run_fact_items_information
[2024-10-21T02:45:13.450+0000] {task_command.py:467} INFO - Running <TaskInstance: elt.transform_data.run_fact_items_information manual__2024-10-21T02:43:24.311342+00:00 [running]> on host 4c00d78d539c
[2024-10-21T02:45:13.523+0000] {abstractoperator.py:778} ERROR - Exception rendering Jinja template for task 'transform_data.run_fact_items_information', field 'sql'. Template: 'dags/sql_files/l2/fact_items_information.sql'
Traceback (most recent call last):
  File "/home/airflow/.local/lib/python3.12/site-packages/airflow/models/abstractoperator.py", line 770, in _do_render_template_fields
    rendered_content = self.render_template(
                       ^^^^^^^^^^^^^^^^^^^^^
  File "/home/airflow/.local/lib/python3.12/site-packages/airflow/template/templater.py", line 168, in render_template
    template = jinja_env.get_template(value)
               ^^^^^^^^^^^^^^^^^^^^^^^^^^^^^
  File "/home/airflow/.local/lib/python3.12/site-packages/jinja2/environment.py", line 1013, in get_template
    return self._load_template(name, globals)
           ^^^^^^^^^^^^^^^^^^^^^^^^^^^^^^^^^^
  File "/home/airflow/.local/lib/python3.12/site-packages/jinja2/environment.py", line 972, in _load_template
    template = self.loader.load(self, name, self.make_globals(globals))
               ^^^^^^^^^^^^^^^^^^^^^^^^^^^^^^^^^^^^^^^^^^^^^^^^^^^^^^^^
  File "/home/airflow/.local/lib/python3.12/site-packages/jinja2/loaders.py", line 126, in load
    source, filename, uptodate = self.get_source(environment, name)
                                 ^^^^^^^^^^^^^^^^^^^^^^^^^^^^^^^^^^
  File "/home/airflow/.local/lib/python3.12/site-packages/jinja2/loaders.py", line 207, in get_source
    raise TemplateNotFound(template)
jinja2.exceptions.TemplateNotFound: dags/sql_files/l2/fact_items_information.sql
[2024-10-21T02:45:13.528+0000] {taskinstance.py:3310} ERROR - Task failed with exception
Traceback (most recent call last):
  File "/home/airflow/.local/lib/python3.12/site-packages/airflow/models/taskinstance.py", line 273, in _run_raw_task
    TaskInstance._execute_task_with_callbacks(
  File "/home/airflow/.local/lib/python3.12/site-packages/airflow/models/taskinstance.py", line 3114, in _execute_task_with_callbacks
    task_orig = self.render_templates(context=context, jinja_env=jinja_env)
                ^^^^^^^^^^^^^^^^^^^^^^^^^^^^^^^^^^^^^^^^^^^^^^^^^^^^^^^^^^^
  File "/home/airflow/.local/lib/python3.12/site-packages/airflow/models/taskinstance.py", line 3533, in render_templates
    original_task.render_template_fields(context, jinja_env)
  File "/home/airflow/.local/lib/python3.12/site-packages/airflow/models/baseoperator.py", line 1419, in render_template_fields
    self._do_render_template_fields(self, self.template_fields, context, jinja_env, set())
  File "/home/airflow/.local/lib/python3.12/site-packages/airflow/models/abstractoperator.py", line 770, in _do_render_template_fields
    rendered_content = self.render_template(
                       ^^^^^^^^^^^^^^^^^^^^^
  File "/home/airflow/.local/lib/python3.12/site-packages/airflow/template/templater.py", line 168, in render_template
    template = jinja_env.get_template(value)
               ^^^^^^^^^^^^^^^^^^^^^^^^^^^^^
  File "/home/airflow/.local/lib/python3.12/site-packages/jinja2/environment.py", line 1013, in get_template
    return self._load_template(name, globals)
           ^^^^^^^^^^^^^^^^^^^^^^^^^^^^^^^^^^
  File "/home/airflow/.local/lib/python3.12/site-packages/jinja2/environment.py", line 972, in _load_template
    template = self.loader.load(self, name, self.make_globals(globals))
               ^^^^^^^^^^^^^^^^^^^^^^^^^^^^^^^^^^^^^^^^^^^^^^^^^^^^^^^^
  File "/home/airflow/.local/lib/python3.12/site-packages/jinja2/loaders.py", line 126, in load
    source, filename, uptodate = self.get_source(environment, name)
                                 ^^^^^^^^^^^^^^^^^^^^^^^^^^^^^^^^^^
  File "/home/airflow/.local/lib/python3.12/site-packages/jinja2/loaders.py", line 207, in get_source
    raise TemplateNotFound(template)
jinja2.exceptions.TemplateNotFound: dags/sql_files/l2/fact_items_information.sql
[2024-10-21T02:45:13.546+0000] {taskinstance.py:1225} INFO - Marking task as FAILED. dag_id=elt, task_id=transform_data.run_fact_items_information, run_id=manual__2024-10-21T02:43:24.311342+00:00, execution_date=20241021T024324, start_date=20241021T024512, end_date=20241021T024513
[2024-10-21T02:45:13.561+0000] {taskinstance.py:340} INFO - ::group::Post task execution logs
[2024-10-21T02:45:13.562+0000] {standard_task_runner.py:124} ERROR - Failed to execute job 92 for task transform_data.run_fact_items_information (dags/sql_files/l2/fact_items_information.sql; 264)
Traceback (most recent call last):
  File "/home/airflow/.local/lib/python3.12/site-packages/airflow/task/task_runner/standard_task_runner.py", line 117, in _start_by_fork
    ret = args.func(args, dag=self.dag)
          ^^^^^^^^^^^^^^^^^^^^^^^^^^^^^
  File "/home/airflow/.local/lib/python3.12/site-packages/airflow/cli/cli_config.py", line 49, in command
    return func(*args, **kwargs)
           ^^^^^^^^^^^^^^^^^^^^^
  File "/home/airflow/.local/lib/python3.12/site-packages/airflow/utils/cli.py", line 115, in wrapper
    return f(*args, **kwargs)
           ^^^^^^^^^^^^^^^^^^
  File "/home/airflow/.local/lib/python3.12/site-packages/airflow/cli/commands/task_command.py", line 483, in task_run
    task_return_code = _run_task_by_selected_method(args, _dag, ti)
                       ^^^^^^^^^^^^^^^^^^^^^^^^^^^^^^^^^^^^^^^^^^^^
  File "/home/airflow/.local/lib/python3.12/site-packages/airflow/cli/commands/task_command.py", line 256, in _run_task_by_selected_method
    return _run_raw_task(args, ti)
           ^^^^^^^^^^^^^^^^^^^^^^^
  File "/home/airflow/.local/lib/python3.12/site-packages/airflow/cli/commands/task_command.py", line 341, in _run_raw_task
    return ti._run_raw_task(
           ^^^^^^^^^^^^^^^^^
  File "/home/airflow/.local/lib/python3.12/site-packages/airflow/utils/session.py", line 97, in wrapper
    return func(*args, session=session, **kwargs)
           ^^^^^^^^^^^^^^^^^^^^^^^^^^^^^^^^^^^^^^
  File "/home/airflow/.local/lib/python3.12/site-packages/airflow/models/taskinstance.py", line 3004, in _run_raw_task
    return _run_raw_task(
           ^^^^^^^^^^^^^^
  File "/home/airflow/.local/lib/python3.12/site-packages/airflow/models/taskinstance.py", line 273, in _run_raw_task
    TaskInstance._execute_task_with_callbacks(
  File "/home/airflow/.local/lib/python3.12/site-packages/airflow/models/taskinstance.py", line 3114, in _execute_task_with_callbacks
    task_orig = self.render_templates(context=context, jinja_env=jinja_env)
                ^^^^^^^^^^^^^^^^^^^^^^^^^^^^^^^^^^^^^^^^^^^^^^^^^^^^^^^^^^^
  File "/home/airflow/.local/lib/python3.12/site-packages/airflow/models/taskinstance.py", line 3533, in render_templates
    original_task.render_template_fields(context, jinja_env)
  File "/home/airflow/.local/lib/python3.12/site-packages/airflow/models/baseoperator.py", line 1419, in render_template_fields
    self._do_render_template_fields(self, self.template_fields, context, jinja_env, set())
  File "/home/airflow/.local/lib/python3.12/site-packages/airflow/models/abstractoperator.py", line 770, in _do_render_template_fields
    rendered_content = self.render_template(
                       ^^^^^^^^^^^^^^^^^^^^^
  File "/home/airflow/.local/lib/python3.12/site-packages/airflow/template/templater.py", line 168, in render_template
    template = jinja_env.get_template(value)
               ^^^^^^^^^^^^^^^^^^^^^^^^^^^^^
  File "/home/airflow/.local/lib/python3.12/site-packages/jinja2/environment.py", line 1013, in get_template
    return self._load_template(name, globals)
           ^^^^^^^^^^^^^^^^^^^^^^^^^^^^^^^^^^
  File "/home/airflow/.local/lib/python3.12/site-packages/jinja2/environment.py", line 972, in _load_template
    template = self.loader.load(self, name, self.make_globals(globals))
               ^^^^^^^^^^^^^^^^^^^^^^^^^^^^^^^^^^^^^^^^^^^^^^^^^^^^^^^^
  File "/home/airflow/.local/lib/python3.12/site-packages/jinja2/loaders.py", line 126, in load
    source, filename, uptodate = self.get_source(environment, name)
                                 ^^^^^^^^^^^^^^^^^^^^^^^^^^^^^^^^^^
  File "/home/airflow/.local/lib/python3.12/site-packages/jinja2/loaders.py", line 207, in get_source
    raise TemplateNotFound(template)
jinja2.exceptions.TemplateNotFound: dags/sql_files/l2/fact_items_information.sql
[2024-10-21T02:45:13.595+0000] {local_task_job_runner.py:266} INFO - Task exited with return code 1
[2024-10-21T02:45:14.113+0000] {taskinstance.py:3900} INFO - 0 downstream tasks scheduled from follow-on schedule check
[2024-10-21T02:45:14.115+0000] {local_task_job_runner.py:245} INFO - ::endgroup::
